2023-01-10 11:36:54 - DEBUG - func: test_plus_normal - input: ((1, 2), {}) -> output: 3
2023-01-10 11:36:54 - ERROR - func: test_plus_error - error message: name 'error' is not defined
Traceback (most recent call last):
  File "C:\JasperWork\Tools\PythonLearn\python_decorator\logger.py", line 83, in inner
    res = func(*args, **kwargs)
  File "C:\JasperWork\Tools\PythonLearn\python_decorator\logger.py", line 100, in test_plus_error
    error  # 不存在的變數，刻意錯誤
NameError: name 'error' is not defined
2023-01-10 11:41:36 - DEBUG - func: test_decorator - input: ((), {}) -> output: None
2023-01-10 11:51:16 - DEBUG - func: test_timer - input: ((1,), {}) -> output: 1
2023-01-10 11:51:44 - DEBUG - func: test_plus_normal - input: ((1, 2), {}) -> output: 3
2023-01-10 11:51:44 - ERROR - func: test_plus_error - error message: name 'error' is not defined
Traceback (most recent call last):
  File "C:\JasperWork\Tools\PythonLearn\python_decorator\logger.py", line 83, in inner
    res = func(*args, **kwargs)
  File "C:\JasperWork\Tools\PythonLearn\python_decorator\logger.py", line 100, in test_plus_error
    error  # 不存在的變數，刻意錯誤
NameError: name 'error' is not defined
2023-01-10 11:51:56 - DEBUG - func: test_timer - input: ((1,), {}) -> output: 1
2023-01-10 11:52:30 - DEBUG - func: test_decorator - input: ((), {}) -> output: None
2023-01-10 13:15:18 - DEBUG - func: test_plus_normal - input: ((1, 2), {}) -> output: 3
2023-01-10 13:15:29 - DEBUG - func: test_plus_normal - input: ((1, 2), {}) -> output: 3
2023-01-10 13:16:40 - DEBUG - func: test_plus_normal - input: ((1, 2), {}) -> output: 3
2023-01-10 13:16:40 - ERROR - func: test_plus_error - error message: name 'error' is not defined
Traceback (most recent call last):
  File "C:\JasperWork\Tools\PythonLearn\python_decorator\logger.py", line 107, in wrapper
    return func(*args, **kwargs)  # 無異常就直接return
  File "C:\JasperWork\Tools\PythonLearn\python_decorator\logger.py", line 144, in test_plus_error
    error  # 不存在的變數，刻意錯誤
NameError: name 'error' is not defined
2023-01-10 13:16:49 - DEBUG - func: test_plus_normal - input: ((1, 2), {}) -> output: 3
2023-01-10 13:16:49 - ERROR - func: test_plus_error - error message: name 'error' is not defined
Traceback (most recent call last):
  File "C:\JasperWork\Tools\PythonLearn\python_decorator\logger.py", line 107, in wrapper
    return func(*args, **kwargs)  # 無異常就直接return
  File "C:\JasperWork\Tools\PythonLearn\python_decorator\logger.py", line 144, in test_plus_error
    error  # 不存在的變數，刻意錯誤
NameError: name 'error' is not defined
2023-01-10 13:16:57 - DEBUG - func: test_plus_normal - input: ((1, 2), {}) -> output: 3
2023-01-10 13:16:57 - ERROR - func: test_plus_error - error message: name 'error' is not defined
Traceback (most recent call last):
  File "C:\JasperWork\Tools\PythonLearn\python_decorator\logger.py", line 107, in wrapper
    return func(*args, **kwargs)  # 無異常就直接return
  File "C:\JasperWork\Tools\PythonLearn\python_decorator\logger.py", line 144, in test_plus_error
    error  # 不存在的變數，刻意錯誤
NameError: name 'error' is not defined
2023-01-10 13:19:32 - DEBUG - func: test_plus_normal - input: ((1, 2), {}) -> output: 3
2023-01-10 13:19:32 - ERROR - func: test_plus_error - error message: name 'res' is not defined
Traceback (most recent call last):
  File "C:\JasperWork\Tools\PythonLearn\python_decorator\logger.py", line 130, in wrapper
    logger.debug(f"func: {func.__name__} - input: {args, kwargs} -> output: {res}")
NameError: name 'res' is not defined
2023-01-10 13:19:32 - DEBUG - func: test_plus_error - time: 0.0 sec.
2023-01-10 13:20:07 - DEBUG - func: test_plus_normal - input: ((1, 2), {}) -> output: 3
2023-01-10 13:20:07 - ERROR - func: test_plus_error - error message: name 'error' is not defined
Traceback (most recent call last):
  File "C:\JasperWork\Tools\PythonLearn\python_decorator\logger.py", line 107, in wrapper
    return func(*args, **kwargs)  # 無異常就直接return
  File "C:\JasperWork\Tools\PythonLearn\python_decorator\logger.py", line 148, in test_plus_error
    error  # 不存在的變數，刻意錯誤
NameError: name 'error' is not defined
2023-01-10 13:21:02 - DEBUG - func: test_plus_normal - input: ((1, 2), {}) -> output: 3
2023-01-10 13:21:02 - ERROR - func: test_plus_error - error message: name 'error' is not defined
Traceback (most recent call last):
  File "C:\JasperWork\Tools\PythonLearn\python_decorator\logger.py", line 107, in wrapper
    return func(*args, **kwargs)  # 無異常就直接return
  File "C:\JasperWork\Tools\PythonLearn\python_decorator\logger.py", line 150, in test_plus_error
    error  # 不存在的變數，刻意錯誤
NameError: name 'error' is not defined
2023-01-10 13:21:15 - DEBUG - func: test_plus_normal - input: ((1, 2), {}) -> output: 3
2023-01-10 13:21:15 - ERROR - func: test_plus_error - error message: name 'res' is not defined
Traceback (most recent call last):
  File "C:\JasperWork\Tools\PythonLearn\python_decorator\logger.py", line 130, in wrapper
    logger.debug(f"func: {func.__name__} - input: {args, kwargs} -> output: {res}")
NameError: name 'res' is not defined
2023-01-10 13:21:15 - DEBUG - func: test_plus_error - time: 0.0 sec.
2023-01-10 13:22:21 - DEBUG - func: test_plus_normal - input: ((1, 2), {}) -> output: 3
2023-01-10 13:22:21 - ERROR - func: test_plus_error - error message: name 'error' is not defined
Traceback (most recent call last):
  File "C:\JasperWork\Tools\PythonLearn\python_decorator\logger.py", line 130, in wrapper
    res = func(*args, **kwargs)
  File "C:\JasperWork\Tools\PythonLearn\python_decorator\logger.py", line 151, in test_plus_error
    error  # 不存在的變數，刻意錯誤
NameError: name 'error' is not defined
2023-01-10 13:22:21 - DEBUG - func: test_plus_error - time: 0.0 sec.
2023-01-10 13:34:56 - DEBUG - func: test_plus_normal - input: ((1, 2), {}) -> output: 3
2023-01-10 13:34:56 - ERROR - func: test_plus_error - error message: name 'error' is not defined
Traceback (most recent call last):
  File "C:\JasperWork\Tools\PythonLearn\python_decorator\logger.py", line 130, in wrapper
    res = func(*args, **kwargs)
  File "C:\JasperWork\Tools\PythonLearn\python_decorator\logger.py", line 151, in test_plus_error
    error  # 不存在的變數，刻意錯誤
NameError: name 'error' is not defined
2023-01-10 13:34:56 - DEBUG - func: test_plus_error - time: 0.0 sec.
2023-01-10 13:35:46 - DEBUG - func: test_timer - input: ((1,), {}) -> output: 1
